{
 "cells": [
  {
   "cell_type": "code",
   "execution_count": 1,
   "metadata": {},
   "outputs": [
    {
     "ename": "OperationalError",
     "evalue": "could not connect to server: Connection refused (0x0000274D/10061)\n\tIs the server running on host \"localhost\" (::1) and accepting\n\tTCP/IP connections on port 26257?\ncould not connect to server: Connection refused (0x0000274D/10061)\n\tIs the server running on host \"localhost\" (127.0.0.1) and accepting\n\tTCP/IP connections on port 26257?\n",
     "output_type": "error",
     "traceback": [
      "\u001b[1;31m---------------------------------------------------------------------------\u001b[0m",
      "\u001b[1;31mOperationalError\u001b[0m                          Traceback (most recent call last)",
      "\u001b[1;32m<ipython-input-1-f162859b9756>\u001b[0m in \u001b[0;36m<module>\u001b[1;34m\u001b[0m\n\u001b[0;32m    150\u001b[0m \u001b[1;33m\u001b[0m\u001b[0m\n\u001b[0;32m    151\u001b[0m \u001b[1;32mif\u001b[0m \u001b[0m__name__\u001b[0m \u001b[1;33m==\u001b[0m \u001b[1;34m'__main__'\u001b[0m\u001b[1;33m:\u001b[0m\u001b[1;33m\u001b[0m\u001b[1;33m\u001b[0m\u001b[0m\n\u001b[1;32m--> 152\u001b[1;33m     \u001b[0mmain\u001b[0m\u001b[1;33m(\u001b[0m\u001b[1;33m)\u001b[0m\u001b[1;33m\u001b[0m\u001b[1;33m\u001b[0m\u001b[0m\n\u001b[0m",
      "\u001b[1;32m<ipython-input-1-f162859b9756>\u001b[0m in \u001b[0;36mmain\u001b[1;34m()\u001b[0m\n\u001b[0;32m    111\u001b[0m         \u001b[0msslcert\u001b[0m\u001b[1;33m=\u001b[0m\u001b[1;34m'certs/client.maxroach.crt'\u001b[0m\u001b[1;33m,\u001b[0m\u001b[1;33m\u001b[0m\u001b[1;33m\u001b[0m\u001b[0m\n\u001b[0;32m    112\u001b[0m         \u001b[0mport\u001b[0m\u001b[1;33m=\u001b[0m\u001b[1;36m26257\u001b[0m\u001b[1;33m,\u001b[0m\u001b[1;33m\u001b[0m\u001b[1;33m\u001b[0m\u001b[0m\n\u001b[1;32m--> 113\u001b[1;33m         \u001b[0mhost\u001b[0m\u001b[1;33m=\u001b[0m\u001b[1;34m'localhost'\u001b[0m\u001b[1;33m\u001b[0m\u001b[1;33m\u001b[0m\u001b[0m\n\u001b[0m\u001b[0;32m    114\u001b[0m     )\n\u001b[0;32m    115\u001b[0m \u001b[1;33m\u001b[0m\u001b[0m\n",
      "\u001b[1;32m~\\Anaconda3\\lib\\site-packages\\psycopg2\\__init__.py\u001b[0m in \u001b[0;36mconnect\u001b[1;34m(dsn, connection_factory, cursor_factory, **kwargs)\u001b[0m\n\u001b[0;32m    125\u001b[0m \u001b[1;33m\u001b[0m\u001b[0m\n\u001b[0;32m    126\u001b[0m     \u001b[0mdsn\u001b[0m \u001b[1;33m=\u001b[0m \u001b[0m_ext\u001b[0m\u001b[1;33m.\u001b[0m\u001b[0mmake_dsn\u001b[0m\u001b[1;33m(\u001b[0m\u001b[0mdsn\u001b[0m\u001b[1;33m,\u001b[0m \u001b[1;33m**\u001b[0m\u001b[0mkwargs\u001b[0m\u001b[1;33m)\u001b[0m\u001b[1;33m\u001b[0m\u001b[1;33m\u001b[0m\u001b[0m\n\u001b[1;32m--> 127\u001b[1;33m     \u001b[0mconn\u001b[0m \u001b[1;33m=\u001b[0m \u001b[0m_connect\u001b[0m\u001b[1;33m(\u001b[0m\u001b[0mdsn\u001b[0m\u001b[1;33m,\u001b[0m \u001b[0mconnection_factory\u001b[0m\u001b[1;33m=\u001b[0m\u001b[0mconnection_factory\u001b[0m\u001b[1;33m,\u001b[0m \u001b[1;33m**\u001b[0m\u001b[0mkwasync\u001b[0m\u001b[1;33m)\u001b[0m\u001b[1;33m\u001b[0m\u001b[1;33m\u001b[0m\u001b[0m\n\u001b[0m\u001b[0;32m    128\u001b[0m     \u001b[1;32mif\u001b[0m \u001b[0mcursor_factory\u001b[0m \u001b[1;32mis\u001b[0m \u001b[1;32mnot\u001b[0m \u001b[1;32mNone\u001b[0m\u001b[1;33m:\u001b[0m\u001b[1;33m\u001b[0m\u001b[1;33m\u001b[0m\u001b[0m\n\u001b[0;32m    129\u001b[0m         \u001b[0mconn\u001b[0m\u001b[1;33m.\u001b[0m\u001b[0mcursor_factory\u001b[0m \u001b[1;33m=\u001b[0m \u001b[0mcursor_factory\u001b[0m\u001b[1;33m\u001b[0m\u001b[1;33m\u001b[0m\u001b[0m\n",
      "\u001b[1;31mOperationalError\u001b[0m: could not connect to server: Connection refused (0x0000274D/10061)\n\tIs the server running on host \"localhost\" (::1) and accepting\n\tTCP/IP connections on port 26257?\ncould not connect to server: Connection refused (0x0000274D/10061)\n\tIs the server running on host \"localhost\" (127.0.0.1) and accepting\n\tTCP/IP connections on port 26257?\n"
     ]
    }
   ],
   "source": [
    "#!/usr/bin/env python3\n",
    "\n",
    "import psycopg2\n",
    "import psycopg2.errorcodes\n",
    "import time\n",
    "import logging\n",
    "import random\n",
    "\n",
    "\n",
    "def create_accounts(conn):\n",
    "    with conn.cursor() as cur:\n",
    "        cur.execute('CREATE TABLE IF NOT EXISTS accounts (id INT PRIMARY KEY, balance INT)')\n",
    "        cur.execute('UPSERT INTO accounts (id, balance) VALUES (1, 1000), (2, 250)')\n",
    "        logging.debug(\"create_accounts(): status message: {}\".format(cur.statusmessage))\n",
    "    conn.commit()\n",
    "\n",
    "\n",
    "def print_balances(conn):\n",
    "    with conn.cursor() as cur:\n",
    "        cur.execute(\"SELECT id, balance FROM accounts\")\n",
    "        logging.debug(\"print_balances(): status message: {}\".format(cur.statusmessage))\n",
    "        rows = cur.fetchall()\n",
    "        conn.commit()\n",
    "        print(\"Balances at {}\".format(time.asctime()))\n",
    "        for row in rows:\n",
    "            print([str(cell) for cell in row])\n",
    "\n",
    "\n",
    "def delete_accounts(conn):\n",
    "    with conn.cursor() as cur:\n",
    "        cur.execute(\"DELETE FROM bank.accounts\")\n",
    "        logging.debug(\"delete_accounts(): status message: {}\".format(cur.statusmessage))\n",
    "    conn.commit()\n",
    "\n",
    "\n",
    "# Wrapper for a transaction.\n",
    "# This automatically re-calls \"op\" with the open transaction as an argument\n",
    "# as long as the database server asks for the transaction to be retried.\n",
    "def run_transaction(conn, op):\n",
    "    retries = 0\n",
    "    max_retries = 3\n",
    "    with conn:\n",
    "        while True:\n",
    "            retries +=1\n",
    "            if retries == max_retries:\n",
    "                err_msg = \"Transaction did not succeed after {} retries\".format(max_retries)\n",
    "                raise ValueError(err_msg)\n",
    "\n",
    "            try:\n",
    "                op(conn)\n",
    "\n",
    "                # If we reach this point, we were able to commit, so we break\n",
    "                # from the retry loop.\n",
    "                break\n",
    "            except psycopg2.Error as e:\n",
    "                logging.debug(\"e.pgcode: {}\".format(e.pgcode))\n",
    "                if e.pgcode == '40001':\n",
    "                    # This is a retry error, so we roll back the current\n",
    "                    # transaction and sleep for a bit before retrying. The\n",
    "                    # sleep time increases for each failed transaction.\n",
    "                    conn.rollback()\n",
    "                    logging.debug(\"EXECUTE SERIALIZATION_FAILURE BRANCH\")\n",
    "                    sleep_ms = (2**retries) * 0.1 * (random.random() + 0.5)\n",
    "                    logging.debug(\"Sleeping {} seconds\".format(sleep_ms))\n",
    "                    time.sleep(sleep_ms)\n",
    "                    continue\n",
    "                else:\n",
    "                    logging.debug(\"EXECUTE NON-SERIALIZATION_FAILURE BRANCH\")\n",
    "                    raise e\n",
    "\n",
    "\n",
    "# This function is used to test the transaction retry logic.  It can be deleted\n",
    "# from production code.\n",
    "def test_retry_loop(conn):\n",
    "    with conn.cursor() as cur:\n",
    "        # The first statement in a transaction can be retried transparently on\n",
    "        # the server, so we need to add a dummy statement so that our\n",
    "        # force_retry() statement isn't the first one.\n",
    "        cur.execute('SELECT now()')\n",
    "        cur.execute(\"SELECT crdb_internal.force_retry('1s'::INTERVAL)\")\n",
    "    logging.debug(\"test_retry_loop(): status message: {}\".format(cur.statusmessage))\n",
    "\n",
    "\n",
    "def transfer_funds(conn, frm, to, amount):\n",
    "    with conn.cursor() as cur:\n",
    "\n",
    "        # Check the current balance.\n",
    "        cur.execute(\"SELECT balance FROM accounts WHERE id = \" + str(frm))\n",
    "        from_balance = cur.fetchone()[0]\n",
    "        if from_balance < amount:\n",
    "            err_msg = \"Insufficient funds in account {}: have {}, need {}\".format(frm, from_balance, amount)\n",
    "            raise RuntimeError(err_msg)\n",
    "\n",
    "        # Perform the transfer.\n",
    "        cur.execute(\"UPDATE accounts SET balance = balance - %s WHERE id = %s\",\n",
    "                    (amount, frm))\n",
    "        cur.execute(\"UPDATE accounts SET balance = balance + %s WHERE id = %s\",\n",
    "                    (amount, to))\n",
    "    conn.commit()\n",
    "    logging.debug(\"transfer_funds(): status message: {}\".format(cur.statusmessage))\n",
    "\n",
    "\n",
    "def main():\n",
    "\n",
    "    conn = psycopg2.connect(\n",
    "        database='bank',\n",
    "        user='maxroach',\n",
    "        sslmode='require',\n",
    "        sslrootcert='certs/ca.crt',\n",
    "        sslkey='certs/client.maxroach.key',\n",
    "        sslcert='certs/client.maxroach.crt',\n",
    "        port=26257,\n",
    "        host='localhost'\n",
    "    )\n",
    "\n",
    "    # Uncomment the below to turn on logging to the console.  This was useful\n",
    "    # when testing transaction retry handling.  It is not necessary for\n",
    "    # production code.\n",
    "    # log_level = getattr(logging, 'DEBUG', None)\n",
    "    # logging.basicConfig(level=log_level)\n",
    "\n",
    "    create_accounts(conn)\n",
    "\n",
    "    print_balances(conn)\n",
    "\n",
    "    amount = 100\n",
    "    fromId = 1\n",
    "    toId = 2\n",
    "\n",
    "    try:\n",
    "        run_transaction(conn, lambda conn: transfer_funds(conn, fromId, toId, amount))\n",
    "\n",
    "        # The function below is used to test the transaction retry logic.  It\n",
    "        # can be deleted from production code.\n",
    "        # run_transaction(conn, lambda conn: test_retry_loop(conn))\n",
    "    except ValueError as ve:\n",
    "        # Below, we print the error and continue on so this example is easy to\n",
    "        # run (and run, and run...).  In real code you should handle this error\n",
    "        # and any others thrown by the database interaction.\n",
    "        logging.debug(\"run_transaction(conn, op) failed: {}\".format(ve))\n",
    "        pass\n",
    "\n",
    "    print_balances(conn)\n",
    "\n",
    "    delete_accounts(conn)\n",
    "\n",
    "    # Close communication with the database.\n",
    "    conn.close()\n",
    "\n",
    "\n",
    "if __name__ == '__main__':\n",
    "    main()"
   ]
  },
  {
   "cell_type": "code",
   "execution_count": null,
   "metadata": {},
   "outputs": [],
   "source": []
  }
 ],
 "metadata": {
  "kernelspec": {
   "display_name": "Python 3",
   "language": "python",
   "name": "python3"
  },
  "language_info": {
   "codemirror_mode": {
    "name": "ipython",
    "version": 3
   },
   "file_extension": ".py",
   "mimetype": "text/x-python",
   "name": "python",
   "nbconvert_exporter": "python",
   "pygments_lexer": "ipython3",
   "version": "3.7.4"
  }
 },
 "nbformat": 4,
 "nbformat_minor": 2
}
